Workbook

Sheet თვითღირებულება
A1: ბარკოდი | B1: დასახელება | C1: წონა კგ | D1: მასალა | E1: დანადგარი | F1: დამზადების დრო წთ | G1: ელექტროენერგიის მოხმარება კვტ/სთ | H1: ელ. ფასი | I1: დახარჯული ელ. ენერგია ლარი | J1: დღგ | K1: 1 კგ მასალის ღირებულება | L1: რეალური წონა კგ | M1: ღირებულება ნედლეულის | N1: დღგ | O1: გასაცემი ხელფასი ცალზე | P1: სულ თვითღირებულება | Q1: დღგ გარეშე | R1: გასაყიდი ფასი | S1: დღგ | T1: დღგ გარეშე | U1: გადასახდელი დღგ | V1: მოგება | W1: მოგების მარჟა | X1: დისტრიბუციის ფასი | Y1: დღგ | Z1: დღგ გარეშე | AA1: დისტრიბუტორის ხელფასი 4% | AB1: მოგება დისტრიბუციის მერე | AC1: მარჟა დისტრიბუციის მერე
A2: 1/DB | B2: ოვალური ვარცლი ლურჯი - L | C2: 1.04 | D2: PP 2 | E2: იტალიური | F2: 1.7 | G2: 120 | H2: 0.32 | I2: =ROUND(F2*G2/60*H2,2) -> 1.09 | J2: =I2-I2/1.18 -> 0.16627119 | K2: 3.5 | L2: 1.25 | M2: =ROUND(L2*K2,2) -> 4.38 | N2: =M2-M2/1.18 -> 0.66813559 | O2: =ROUND(150/8/60*F2,2) -> 0.53 | P2: =ROUND(O2+M2+I2,2) -> 6 | Q2: =P2-N2-J2 -> 5.1655932 | R2: 7.65 | S2: =R2-R2/1.18 -> 1.1669492 | T2: =R2-S2 -> 6.4830508 | U2: =S2-N2-J2 -> 0.33254237 | V2: =T2-Q2 -> 1.3174576 | W2: =V2/R2 -> 0.17221668 | X2: 7.3 | Y2: =X2-Z2 -> 1.1135593 | Z2: =X2/1.18 -> 6.1864407 | AA2: =X2*4% -> 0.292 | AB2: =Z2-Q2-AA2 -> 0.72884746 | AC2: =AB2/X2 -> 0.099842117
A3: 2/DB | B3: ოვალური ვარცლი ლურჯი - M | C3: 0.75 | D3: PP 2 | E3: იტალიური | F3: 1.7 | G3: 120 | H3: 0.32 | I3: =ROUND(F3*G3/60*H3,2) -> 1.09 | J3: =I3-I3/1.18 -> 0.16627119 | K3: 3.5 | L3: 0.9 | M3: =ROUND(L3*K3,2) -> 3.15 | N3: =M3-M3/1.18 -> 0.48050847 | O3: =ROUND(150/8/60*F3,2) -> 0.53 | P3: =ROUND(O3+M3+I3,2) -> 4.77 | Q3: =P3-N3-J3 -> 4.1232203 | R3: 7 | S3: =R3-R3/1.18 -> 1.0677966 | T3: =R3-S3 -> 5.9322034 | U3: =S3-N3-J3 -> 0.42101695 | V3: =T3-Q3 -> 1.8089831 | W3: =V3/R3 -> 0.25842615 | X3: 5.95 | Y3: =X3-Z3 -> 0.90762712 | Z3: =X3/1.18 -> 5.0423729 | AA3: =X3*4% -> 0.238 | AB3: =Z3-Q3-AA3 -> 0.68115254 | AC3: =AB3/X3 -> 0.11447942
A4: 3/DB | B4: ოვალური ვარცლი ლურჯი - S | C4: 0.5 | D4: PP 2 | E4: იტალიური | F4: 1.7 | G4: 120 | H4: 0.32 | I4: =ROUND(F4*G4/60*H4,2) -> 1.09 | J4: =I4-I4/1.18 -> 0.16627119 | K4: 3.5 | L4: 0.6 | M4: =ROUND(L4*K4,2) -> 2.1 | N4: =M4-M4/1.18 -> 0.32033898 | O4: =ROUND(150/8/60*F4,2) -> 0.53 | P4: =ROUND(O4+M4+I4,2) -> 3.72 | Q4: =P4-N4-J4 -> 3.2333898 | R4: 6.4 | S4: =R4-R4/1.18 -> 0.97627119 | T4: =R4-S4 -> 5.4237288 | U4: =S4-N4-J4 -> 0.48966102 | V4: =T4-Q4 -> 2.190339 | W4: =V4/R4 -> 0.34224047 | X4: 5.45 | Y4: =X4-Z4 -> 0.83135593 | Z4: =X4/1.18 -> 4.6186441 | AA4: =X4*4% -> 0.218 | AB4: =Z4-Q4-AA4 -> 1.1672542 | AC4: =AB4/X4 -> 0.21417509
A5: 4/DB | B5: მრგვალი ვარცლი ლურჯი - S | C5: 0.41 | D5: PP 2 | E5: იტალიური/პატარა გერმანული | F5: 1.7 | G5: 100 | H5: 0.32 | I5: =ROUND(F5*G5/60*H5,2) -> 0.91 | J5: =I5-I5/1.18 -> 0.13881356 | K5: 3.5 | L5: 0.49 | M5: =ROUND(L5*K5,2) -> 1.72 | N5: =M5-M5/1.18 -> 0.26237288 | O5: =ROUND(150/8/60*F5,2) -> 0.53 | P5: =ROUND(O5+M5+I5,2) -> 3.16 | Q5: =P5-N5-J5 -> 2.7588136 | R5: 4.5 | S5: =R5-R5/1.18 -> 0.68644068 | T5: =R5-S5 -> 3.8135593 | U5: =S5-N5-J5 -> 0.28525424 | V5: =T5-Q5 -> 1.0547458 | W5: =V5/R5 -> 0.23438795 | X5: 3.9 | Y5: =X5-Z5 -> 0.59491525 | Z5: =X5/1.18 -> 3.3050847 | AA5: =X5*4% -> 0.156 | AB5: =Z5-Q5-AA5 -> 0.39027119 | AC5: =AB5/X5 -> 0.10006953
A6: 5/1/BL | B6: ინდუსტრიული ვარცლი შავი | C6: 1.155 | D6: აკუმულატორი 2 | E6: ხუთკილოიანი/დიდი გერმანული | F6: 2 | G6: 180 | H6: 0.32 | I6: =ROUND(F6*G6/60*H6,2) -> 1.92 | J6: =I6-I6/1.18 -> 0.29288136 | K6: 3.5 | L6: 1.39 | M6: =ROUND(L6*K6,2) -> 4.87 | N6: =M6-M6/1.18 -> 0.74288136 | O6: =ROUND(150/8/60*F6,2) -> 0.63 | P6: =ROUND(O6+M6+I6,2) -> 7.42 | Q6: =P6-N6-J6 -> 6.3842373 | R6: 15 | S6: =R6-R6/1.18 -> 2.2881356 | T6: =R6-S6 -> 12.711864 | U6: =S6-N6-J6 -> 1.2523729 | V6: =T6-Q6 -> 6.3276271 | W6: =V6/R6 -> 0.42184181 | X6: 12.75 | Y6: =X6-Z6 -> 1.9449153 | Z6: =X6/1.18 -> 10.805085 | AA6: =X6*4% -> 0.51 | AB6: =Z6-Q6-AA6 -> 3.9108475 | AC6: =AB6/X6 -> 0.30673313
A7: 5/DB | B7: უნივერსალური ვარცლი ლურჯი | C7: 1.17 | D7: PP 2 | E7: ხუთკილოიანი/დიდი გერმანული | F7: 2 | G7: 180 | H7: 0.32 | I7: =ROUND(F7*G7/60*H7,2) -> 1.92 | J7: =I7-I7/1.18 -> 0.29288136 | K7: 3.5 | L7: 1.4 | M7: =ROUND(L7*K7,2) -> 4.9 | N7: =M7-M7/1.18 -> 0.74745763 | O7: =ROUND(150/8/60*F7,2) -> 0.63 | P7: =ROUND(O7+M7+I7,2) -> 7.45 | Q7: =P7-N7-J7 -> 6.409661 | R7: 10 | S7: =R7-R7/1.18 -> 1.5254237 | T7: =R7-S7 -> 8.4745763 | U7: =S7-N7-J7 -> 0.48508475 | V7: =T7-Q7 -> 2.0649153 | W7: =V7/R7 -> 0.20649153 | X7: 9 | Y7: =X7-Z7 -> 1.3728814 | Z7: =X7/1.18 -> 7.6271186 | AA7: =X7*4% -> 0.36 | AB7: =Z7-Q7-AA7 -> 0.85745763 | AC7: =AB7/X7 -> 0.09527307
A8: 6/DB | B8: გობი ერგონომიური სახელურებით ლურჯი - L | C8: 0.565 | D8: PE 2, PP 2 | E8: იტალიური/პატარა გერმანული | F8: 1.7 | G8: 100 | H8: 0.32 | I8: =ROUND(F8*G8/60*H8,2) -> 0.91 | J8: =I8-I8/1.18 -> 0.13881356 | K8: 3.5 | L8: 0.68 | M8: =ROUND(L8*K8,2) -> 2.38 | N8: =M8-M8/1.18 -> 0.36305085 | O8: =ROUND(150/8/60*F8,2) -> 0.53 | P8: =ROUND(O8+M8+I8,2) -> 3.82 | Q8: =P8-N8-J8 -> 3.3181356 | R8: 5.5 | S8: =R8-R8/1.18 -> 0.83898305 | T8: =R8-S8 -> 4.6610169 | U8: =S8-N8-J8 -> 0.33711864 | V8: =T8-Q8 -> 1.3428814 | W8: =V8/R8 -> 0.24416025 | X8: 4.7 | Y8: =X8-Z8 -> 0.71694915 | Z8: =X8/1.18 -> 3.9830508 | AA8: =X8*4% -> 0.188 | AB8: =Z8-Q8-AA8 -> 0.47691525 | AC8: =AB8/X8 -> 0.10147133
A9: 6/G | B9: გობი ერგონომიური სახელურებით მწვანე - L | C9: 0.565 | D9: PE 2, PP 2 | E9: იტალიური/პატარა გერმანული | F9: 1.7 | G9: 100 | H9: 0.32 | I9: =ROUND(F9*G9/60*H9,2) -> 0.91 | J9: =I9-I9/1.18 -> 0.13881356 | K9: 3.5 | L9: 0.68 | M9: =ROUND(L9*K9,2) -> 2.38 | N9: =M9-M9/1.18 -> 0.36305085 | O9: =ROUND(150/8/60*F9,2) -> 0.53 | P9: =ROUND(O9+M9+I9,2) -> 3.82 | Q9: =P9-N9-J9 -> 3.3181356 | R9: 5.5 | S9: =R9-R9/1.18 -> 0.83898305 | T9: =R9-S9 -> 4.6610169 | U9: =S9-N9-J9 -> 0.33711864 | V9: =T9-Q9 -> 1.3428814 | W9: =V9/R9 -> 0.24416025 | X9: 4.7 | Y9: =X9-Z9 -> 0.71694915 | Z9: =X9/1.18 -> 3.9830508 | AA9: =X9*4% -> 0.188 | AB9: =Z9-Q9-AA9 -> 0.47691525 | AC9: =AB9/X9 -> 0.10147133
A10: 6/R | B10: გობი ერგონომიური სახელურებით წითელი - L | C10: 0.565 | D10: PE 2, PP 2 | E10: იტალიური/პატარა გერმანული | F10: 1.7 | G10: 100 | H10: 0.32 | I10: =ROUND(F10*G10/60*H10,2) -> 0.91 | J10: =I10-I10/1.18 -> 0.13881356 | K10: 3.5 | L10: 0.68 | M10: =ROUND(L10*K10,2) -> 2.38 | N10: =M10-M10/1.18 -> 0.36305085 | O10: =ROUND(150/8/60*F10,2) -> 0.53 | P10: =ROUND(O10+M10+I10,2) -> 3.82 | Q10: =P10-N10-J10 -> 3.3181356 | R10: 5.5 | S10: =R10-R10/1.18 -> 0.83898305 | T10: =R10-S10 -> 4.6610169 | U10: =S10-N10-J10 -> 0.33711864 | V10: =T10-Q10 -> 1.3428814 | W10: =V10/R10 -> 0.24416025 | X10: 4.7 | Y10: =X10-Z10 -> 0.71694915 | Z10: =X10/1.18 -> 3.9830508 | AA10: =X10*4% -> 0.188 | AB10: =Z10-Q10-AA10 -> 0.47691525 | AC10: =AB10/X10 -> 0.10147133
A11: 7/DB | B11: გობი - M ლურჯი | C11: 0.32 | D11: PP 2 | E11: ნახევრკილოიანი | F11: 1.7 | G11: 70 | H11: 0.32 | I11: =ROUND(F11*G11/60*H11,2) -> 0.63 | J11: =I11-I11/1.18 -> 0.096101695 | K11: 3.5 | L11: 0.38 | M11: =ROUND(L11*K11,2) -> 1.33 | N11: =M11-M11/1.18 -> 0.20288136 | O11: =ROUND(150/8/60*F11,2) -> 0.53 | P11: =ROUND(O11+M11+I11,2) -> 2.49 | Q11: =P11-N11-J11 -> 2.1910169 | R11: 4.5 | S11: =R11-R11/1.18 -> 0.68644068 | T11: =R11-S11 -> 3.8135593 | U11: =S11-N11-J11 -> 0.38745763 | V11: =T11-Q11 -> 1.6225424 | W11: =V11/R11 -> 0.36056497 | X11: 3.85 | Y11: =X11-Z11 -> 0.58728814 | Z11: =X11/1.18 -> 3.2627119 | AA11: =X11*4% -> 0.154 | AB11: =Z11-Q11-AA11 -> 0.91769492 | AC11: =AB11/X11 -> 0.23836232
A12: 8/DB | B12: თასი ლურჯი - S | C12: 0.35 | D12: PE 2, PP 2 | E12: ნახევრკილოიანი | F12: 1.3 | G12: 70 | H12: 0.32 | I12: =ROUND(F12*G12/60*H12,2) -> 0.49 | J12: =I12-I12/1.18 -> 0.074745763 | K12: 3.5 | L12: 0.42 | M12: =ROUND(L12*K12,2) -> 1.47 | N12: =M12-M12/1.18 -> 0.22423729 | O12: =ROUND(150/8/60*F12,2) -> 0.41 | P12: =ROUND(O12+M12+I12,2) -> 2.37 | Q12: =P12-N12-J12 -> 2.0710169 | R12: 3.5 | S12: =R12-R12/1.18 -> 0.53389831 | T12: =R12-S12 -> 2.9661017 | U12: =S12-N12-J12 -> 0.23491525 | V12: =T12-Q12 -> 0.89508475 | W12: =V12/R12 -> 0.2557385 | X12: 3 | Y12: =X12-Z12 -> 0.45762712 | Z12: =X12/1.18 -> 2.5423729 | AA12: =X12*4% -> 0.12 | AB12: =Z12-Q12-AA12 -> 0.35135593 | AC12: =AB12/X12 -> 0.11711864
A13: 8/G | B13: თასი მწვანე - S | C13: 0.35 | D13: PE 2, PP 2 | E13: ნახევრკილოიანი | F13: 1.3 | G13: 70 | H13: 0.32 | I13: =ROUND(F13*G13/60*H13,2) -> 0.49 | J13: =I13-I13/1.18 -> 0.074745763 | K13: 3.5 | L13: 0.42 | M13: =ROUND(L13*K13,2) -> 1.47 | N13: =M13-M13/1.18 -> 0.22423729 | O13: =ROUND(150/8/60*F13,2) -> 0.41 | P13: =ROUND(O13+M13+I13,2) -> 2.37 | Q13: =P13-N13-J13 -> 2.0710169 | R13: 3.5 | S13: =R13-R13/1.18 -> 0.53389831 | T13: =R13-S13 -> 2.9661017 | U13: =S13-N13-J13 -> 0.23491525 | V13: =T13-Q13 -> 0.89508475 | W13: =V13/R13 -> 0.2557385 | X13: 3 | Y13: =X13-Z13 -> 0.45762712 | Z13: =X13/1.18 -> 2.5423729 | AA13: =X13*4% -> 0.12 | AB13: =Z13-Q13-AA13 -> 0.35135593 | AC13: =AB13/X13 -> 0.11711864
... A101: 74/DB | B101: ხილ-ბოსტნეულის ბადისებრი ყუთი ლურჯი | C101: 0.416 | D101: PP 2, აკუმულატორი | E101: ხუთკილოიანი/დიდი გერმანული | F101: 0.75 | G101: 180 | H101: 0.32 | I101: =ROUND(F101*G101/60*H101,2) -> 0.72 | J101: =I101-I101/1.18 -> 0.10983051 | K101: 3.5 | L101: 0.5 | M101: =ROUND(L101*K101,2) -> 1.75 | N101: =M101-M101/1.18 -> 0.26694915 | O101: =ROUND(150/8/60*F101,2) -> 0.23 | P101: =ROUND(O101+M101+I101,2) -> 2.7 | Q101: =P101-N101-J101 -> 2.3232203 | R101: 3 | S101: =R101-R101/1.18 -> 0.45762712 | T101: =R101-S101 -> 2.5423729 | U101: =S101-N101-J101 -> 0.080847458 | V101: =T101-Q101 -> 0.21915254 | W101: =V101/R101 -> 0.073050847 | X101: 3 | Y101: =X101-Z101 -> 0.45762712 | Z101: =X101/1.18 -> 2.5423729 | AA101: =X101*4% -> 0.12 | AB101: =Z101-Q101-AA101 -> 0.099152542 | AC101: =AB101/X101 -> 0.033050847

Sheet პროდუქტების დასათვლელი
A1: კოდი | B1: პროდუქტი | C1: დამზადების დრო | D1: ერთეულზე დახარჯული ხელფასი | E1: რეალური წონა | F1: გამოყენებული მასალის ღირებულება | G1: დამზაებაზე დახარჯული მასალის ღირებულება | H1: ერთეულზე დახარჯული ელ. ენერგიის ღირებულება | I1: ერთეულის თვითღირებულება | J1: დღგ გარეშე თვიღღ | K1: ცალი | L1: გასაყიდი ფასი | M1: გასაყიდი ფასი დღგ გარეშე | N1: დამზადების დრო წთ | O1: დახარჯული ელ. ენერგია ლარი | P1: დამზადების დრო დღე | Q1: სამუსაო საათების ღირებულება | R1: გამოსაყენებელი მასალა კგ | S1: გამოსაყენებელი მასალის ღირებულება | T1: თვითRir. | U1: თვითღირებულება დღგ გარეშე | V1: გასაყიდი ფასი სულ | W1: გასაყიდი ფასი დღგ გარეშე | X1: მოგება
A2: 1/DB | B2: =VLOOKUP(A2,თვითღირებულება!A:AC,2,0) -> ოვალური ვარცლი ლურჯი - L | C2: =VLOOKUP(A2,თვითღირებულება!A:AC,6,0) -> 1.7 | D2: =VLOOKUP(A2,თვითღირებულება!A:AC,15,0) -> 0.53 | E2: =VLOOKUP(A2,თვითღირებულება!A:AC,12,0) -> 1.25 | F2: =VLOOKUP(A2,თვითღირებულება!A:AC,11,0) -> 3.5 | G2: =E2*F2 -> 4.375 | H2: =VLOOKUP(A2,თვითღირებულება!A:AC,9,0) -> 1.09 | I2: =VLOOKUP(A2,თვითღირებულება!A:AC,16,0) -> 6 | J2: =VLOOKUP(A2,თვითღირებულება!A:AC,17,0) -> 5.1655932 | K2: 0 | L2: =VLOOKUP(A2,[1]Sheet!$A:$J,10,0) -> 6.5 | M2: =L2/1.18 -> 5.5084746 | N2: =K2*C2 -> 0 | O2: =K2*H2 -> 0 | P2: =N2/8/60 -> 0 | Q2: =K2*D2 -> 0 | R2: =K2*E2 -> 0 | S2: =K2*E2*F2 -> 0 | T2: =K2*I2 -> 0 | U2: =K2*J2 -> 0 | V2: =K2*L2 -> 0 | W2: =V2/1.18 -> 0 | X2: =W2-U2 -> 0
A3: 2/DB | B3: =VLOOKUP(A3,თვითღირებულება!A:AC,2,0) -> ოვალური ვარცლი ლურჯი - M | C3: =VLOOKUP(A3,თვითღირებულება!A:AC,6,0) -> 1.7 | D3: =VLOOKUP(A3,თვითღირებულება!A:AC,15,0) -> 0.53 | E3: =VLOOKUP(A3,თვითღირებულება!A:AC,12,0) -> 0.9 | F3: =VLOOKUP(A3,თვითღირებულება!A:AC,11,0) -> 3.5 | G3: =E3*F3 -> 3.15 | H3: =VLOOKUP(A3,თვითღირებულება!A:AC,9,0) -> 1.09 | I3: =VLOOKUP(A3,თვითღირებულება!A:AC,16,0) -> 4.77 | J3: =VLOOKUP(A3,თვითღირებულება!A:AC,17,0) -> 4.1232203 | K3: =VLOOKUP(A3,[1]Sheet!$A:$G,7,0) -> 46 | L3: =VLOOKUP(A3,[1]Sheet!$A:$J,10,0) -> 5.95 | M3: =L3/1.18 -> 5.0423729 | N3: =K3*C3 -> 78.2 | O3: =K3*H3 -> 50.14 | P3: =N3/8/60 -> 0.16291667 | Q3: =K3*D3 -> 24.38 | R3: =K3*E3 -> 41.4 | S3: =K3*E3*F3 -> 144.9 | T3: =K3*I3 -> 219.42 | U3: =K3*J3 -> 189.66814 | V3: =K3*L3 -> 273.7 | W3: =V3/1.18 -> 231.94915 | X3: =W3-U3 -> 42.281017
A4: 3/DB | B4: =VLOOKUP(A4,თვითღირებულება!A:AC,2,0) -> ოვალური ვარცლი ლურჯი - S | C4: =VLOOKUP(A4,თვითღირებულება!A:AC,6,0) -> 1.7 | D4: =VLOOKUP(A4,თვითღირებულება!A:AC,15,0) -> 0.53 | E4: =VLOOKUP(A4,თვითღირებულება!A:AC,12,0) -> 0.6 | F4: =VLOOKUP(A4,თვითღირებულება!A:AC,11,0) -> 3.5 | G4: =E4*F4 -> 2.1 | H4: =VLOOKUP(A4,თვითღირებულება!A:AC,9,0) -> 1.09 | I4: =VLOOKUP(A4,თვითღირებულება!A:AC,16,0) -> 3.72 | J4: =VLOOKUP(A4,თვითღირებულება!A:AC,17,0) -> 3.2333898 | K4: =VLOOKUP(A4,[1]Sheet!$A:$G,7,0) -> 49 | L4: =VLOOKUP(A4,[1]Sheet!$A:$J,10,0) -> 5.45 | M4: =L4/1.18 -> 4.6186441 | N4: =K4*C4 -> 83.3 | O4: =K4*H4 -> 53.41 | P4: =N4/8/60 -> 0.17354167 | Q4: =K4*D4 -> 25.97 | R4: =K4*E4 -> 29.4 | S4: =K4*E4*F4 -> 102.9 | T4: =K4*I4 -> 182.28 | U4: =K4*J4 -> 158.4361 | V4: =K4*L4 -> 267.05 | W4: =V4/1.18 -> 226.31356 | X4: =W4-U4 -> 67.877458
A5: 4/DB | B5: =VLOOKUP(A5,თვითღირებულება!A:AC,2,0) -> მრგვალი ვარცლი ლურჯი - S | C5: =VLOOKUP(A5,თვითღირებულება!A:AC,6,0) -> 1.7 | D5: =VLOOKUP(A5,თვითღირებულება!A:AC,15,0) -> 0.53 | E5: =VLOOKUP(A5,თვითღირებულება!A:AC,12,0) -> 0.49 | F5: =VLOOKUP(A5,თვითღირებულება!A:AC,11,0) -> 3.5 | G5: =E5*F5 -> 1.715 | H5: =VLOOKUP(A5,თვითღირებულება!A:AC,9,0) -> 0.91 | I5: =VLOOKUP(A5,თვითღირებულება!A:AC,16,0) -> 3.16 | J5: =VLOOKUP(A5,თვითღირებულება!A:AC,17,0) -> 2.7588136 | K5: =VLOOKUP(A5,[1]Sheet!$A:$G,7,0) -> 50 | L5: =VLOOKUP(A5,[1]Sheet!$A:$J,10,0) -> 3.5 | M5: =L5/1.18 -> 2.9661017 | N5: =K5*C5 -> 85 | O5: =K5*H5 -> 45.5 | P5: =N5/8/60 -> 0.17708333 | Q5: =K5*D5 -> 26.5 | R5: =K5*E5 -> 24.5 | S5: =K5*E5*F5 -> 85.75 | T5: =K5*I5 -> 158 | U5: =K5*J5 -> 137.94068 | V5: =K5*L5 -> 175 | W5: =V5/1.18 -> 148.30508 | X5: =W5-U5 -> 10.364407
A6: 5/1/BL | B6: =VLOOKUP(A6,თვითღირებულება!A:AC,2,0) -> ინდუსტრიული ვარცლი შავი | C6: =VLOOKUP(A6,თვითღირებულება!A:AC,6,0) -> 2 | D6: =VLOOKUP(A6,თვითღირებულება!A:AC,15,0) -> 0.63 | E6: =VLOOKUP(A6,თვითღირებულება!A:AC,12,0) -> 1.39 | F6: =VLOOKUP(A6,თვითღირებულება!A:AC,11,0) -> 3.5 | G6: =E6*F6 -> 4.865 | H6: =VLOOKUP(A6,თვითღირებულება!A:AC,9,0) -> 1.92 | I6: =VLOOKUP(A6,თვითღირებულება!A:AC,16,0) -> 7.42 | J6: =VLOOKUP(A6,თვითღირებულება!A:AC,17,0) -> 6.3842373 | K6: =VLOOKUP(A6,[1]Sheet!$A:$G,7,0) -> 0 | L6: =VLOOKUP(A6,[1]Sheet!$A:$J,10,0) -> 12.75 | M6: =L6/1.18 -> 10.805085 | N6: =K6*C6 -> 0 | O6: =K6*H6 -> 0 | P6: =N6/8/60 -> 0 | Q6: =K6*D6 -> 0 | R6: =K6*E6 -> 0 | S6: =K6*E6*F6 -> 0 | T6: =K6*I6 -> 0 | U6: =K6*J6 -> 0 | V6: =K6*L6 -> 0 | W6: =V6/1.18 -> 0 | X6: =W6-U6 -> 0
A7: 5/DB | B7: =VLOOKUP(A7,თვითღირებულება!A:AC,2,0) -> უნივერსალური ვარცლი ლურჯი | C7: =VLOOKUP(A7,თვითღირებულება!A:AC,6,0) -> 2 | D7: =VLOOKUP(A7,თვითღირებულება!A:AC,15,0) -> 0.63 | E7: =VLOOKUP(A7,თვითღირებულება!A:AC,12,0) -> 1.4 | F7: =VLOOKUP(A7,თვითღირებულება!A:AC,11,0) -> 3.5 | G7: =E7*F7 -> 4.9 | H7: =VLOOKUP(A7,თვითღირებულება!A:AC,9,0) -> 1.92 | I7: =VLOOKUP(A7,თვითღირებულება!A:AC,16,0) -> 7.45 | J7: =VLOOKUP(A7,თვითღირებულება!A:AC,17,0) -> 6.409661 | K7: =VLOOKUP(A7,[1]Sheet!$A:$G,7,0) -> 0 | L7: =VLOOKUP(A7,[1]Sheet!$A:$J,10,0) -> 8.5 | M7: =L7/1.18 -> 7.2033898 | N7: =K7*C7 -> 0 | O7: =K7*H7 -> 0 | P7: =N7/8/60 -> 0 | Q7: =K7*D7 -> 0 | R7: =K7*E7 -> 0 | S7: =K7*E7*F7 -> 0 | T7: =K7*I7 -> 0 | U7: =K7*J7 -> 0 | V7: =K7*L7 -> 0 | W7: =V7/1.18 -> 0 | X7: =W7-U7 -> 0
A8: 6/DB | B8: =VLOOKUP(A8,თვითღირებულება!A:AC,2,0) -> გობი ერგონომიური სახელურებით ლურჯი - L | C8: =VLOOKUP(A8,თვითღირებულება!A:AC,6,0) -> 1.7 | D8: =VLOOKUP(A8,თვითღირებულება!A:AC,15,0) -> 0.53 | E8: =VLOOKUP(A8,თვითღირებულება!A:AC,12,0) -> 0.68 | F8: =VLOOKUP(A8,თვითღირებულება!A:AC,11,0) -> 3.5 | G8: =E8*F8 -> 2.38 | H8: =VLOOKUP(A8,თვითღირებულება!A:AC,9,0) -> 0.91 | I8: =VLOOKUP(A8,თვითღირებულება!A:AC,16,0) -> 3.82 | J8: =VLOOKUP(A8,თვითღირებულება!A:AC,17,0) -> 3.3181356 | K8: =VLOOKUP(A8,[1]Sheet!$A:$G,7,0) -> 26 | L8: =VLOOKUP(A8,[1]Sheet!$A:$J,10,0) -> 4.65 | M8: =L8/1.18 -> 3.940678 | N8: =K8*C8 -> 44.2 | O8: =K8*H8 -> 23.66 | P8: =N8/8/60 -> 0.092083333 | Q8: =K8*D8 -> 13.78 | R8: =K8*E8 -> 17.68 | S8: =K8*E8*F8 -> 61.88 | T8: =K8*I8 -> 99.32 | U8: =K8*J8 -> 86.271525 | V8: =K8*L8 -> 120.9 | W8: =V8/1.18 -> 102.45763 | X8: =W8-U8 -> 16.186102
A9: 6/G | B9: =VLOOKUP(A9,თვითღირებულება!A:AC,2,0) -> გობი ერგონომიური სახელურებით მწვანე - L | C9: =VLOOKUP(A9,თვითღირებულება!A:AC,6,0) -> 1.7 | D9: =VLOOKUP(A9,თვითღირებულება!A:AC,15,0) -> 0.53 | E9: =VLOOKUP(A9,თვითღირებულება!A:AC,12,0) -> 0.68 | F9: =VLOOKUP(A9,თვითღირებულება!A:AC,11,0) -> 3.5 | G9: =E9*F9 -> 2.38 | H9: =VLOOKUP(A9,თვითღირებულება!A:AC,9,0) -> 0.91 | I9: =VLOOKUP(A9,თვითღირებულება!A:AC,16,0) -> 3.82 | J9: =VLOOKUP(A9,თვითღირებულება!A:AC,17,0) -> 3.3181356 | K9: =VLOOKUP(A9,[1]Sheet!$A:$G,7,0) -> 10 | L9: =VLOOKUP(A9,[1]Sheet!$A:$J,10,0) -> 4.65 | M9: =L9/1.18 -> 3.940678 | N9: =K9*C9 -> 17 | O9: =K9*H9 -> 9.1 | P9: =N9/8/60 -> 0.035416667 | Q9: =K9*D9 -> 5.3 | R9: =K9*E9 -> 6.8 | S9: =K9*E9*F9 -> 23.8 | T9: =K9*I9 -> 38.2 | U9: =K9*J9 -> 33.181356 | V9: =K9*L9 -> 46.5 | W9: =V9/1.18 -> 39.40678 | X9: =W9-U9 -> 6.2254237
A10: 6/R | B10: =VLOOKUP(A10,თვითღირებულება!A:AC,2,0) -> გობი ერგონომიური სახელურებით წითელი - L | C10: =VLOOKUP(A10,თვითღირებულება!A:AC,6,0) -> 1.7 | D10: =VLOOKUP(A10,თვითღირებულება!A:AC,15,0) -> 0.53 | E10: =VLOOKUP(A10,თვითღირებულება!A:AC,12,0) -> 0.68 | F10: =VLOOKUP(A10,თვითღირებულება!A:AC,11,0) -> 3.5 | G10: =E10*F10 -> 2.38 | H10: =VLOOKUP(A10,თვითღირებულება!A:AC,9,0) -> 0.91 | I10: =VLOOKUP(A10,თვითღირებულება!A:AC,16,0) -> 3.82 | J10: =VLOOKUP(A10,თვითღირებულება!A:AC,17,0) -> 3.3181356 | K10: =VLOOKUP(A10,[1]Sheet!$A:$G,7,0) -> 24 | L10: =VLOOKUP(A10,[1]Sheet!$A:$J,10,0) -> 4.65 | M10: =L10/1.18 -> 3.940678 | N10: =K10*C10 -> 40.8 | O10: =K10*H10 -> 21.84 | P10: =N10/8/60 -> 0.085 | Q10: =K10*D10 -> 12.72 | R10: =K10*E10 -> 16.32 | S10: =K10*E10*F10 -> 57.12 | T10: =K10*I10 -> 91.68 | U10: =K10*J10 -> 79.635254 | V10: =K10*L10 -> 111.6 | W10: =V10/1.18 -> 94.576271 | X10: =W10-U10 -> 14.941017
A11: 7/DB | B11: =VLOOKUP(A11,თვითღირებულება!A:AC,2,0) -> გობი - M ლურჯი | C11: =VLOOKUP(A11,თვითღირებულება!A:AC,6,0) -> 1.7 | D11: =VLOOKUP(A11,თვითღირებულება!A:AC,15,0) -> 0.53 | E11: =VLOOKUP(A11,თვითღირებულება!A:AC,12,0) -> 0.38 | F11: =VLOOKUP(A11,თვითღირებულება!A:AC,11,0) -> 3.5 | G11: =E11*F11 -> 1.33 | H11: =VLOOKUP(A11,თვითღირებულება!A:AC,9,0) -> 0.63 | I11: =VLOOKUP(A11,თვითღირებულება!A:AC,16,0) -> 2.49 | J11: =VLOOKUP(A11,თვითღირებულება!A:AC,17,0) -> 2.1910169 | K11: =VLOOKUP(A11,[1]Sheet!$A:$G,7,0) -> 0 | L11: =VLOOKUP(A11,[1]Sheet!$A:$J,10,0) -> 3.85 | M11: =L11/1.18 -> 3.2627119 | N11: =K11*C11 -> 0 | O11: =K11*H11 -> 0 | P11: =N11/8/60 -> 0 | Q11: =K11*D11 -> 0 | R11: =K11*E11 -> 0 | S11: =K11*E11*F11 -> 0 | T11: =K11*I11 -> 0 | U11: =K11*J11 -> 0 | V11: =K11*L11 -> 0 | W11: =V11/1.18 -> 0 | X11: =W11-U11 -> 0
A12: 8/DB | B12: =VLOOKUP(A12,თვითღირებულება!A:AC,2,0) -> თასი ლურჯი - S | C12: =VLOOKUP(A12,თვითღირებულება!A:AC,6,0) -> 1.3 | D12: =VLOOKUP(A12,თვითღირებულება!A:AC,15,0) -> 0.41 | E12: =VLOOKUP(A12,თვითღირებულება!A:AC,12,0) -> 0.42 | F12: =VLOOKUP(A12,თვითღირებულება!A:AC,11,0) -> 3.5 | G12: =E12*F12 -> 1.47 | H12: =VLOOKUP(A12,თვითღირებულება!A:AC,9,0) -> 0.49 | I12: =VLOOKUP(A12,თვითღირებულება!A:AC,16,0) -> 2.37 | J12: =VLOOKUP(A12,თვითღირებულება!A:AC,17,0) -> 2.0710169 | K12: =VLOOKUP(A12,[1]Sheet!$A:$G,7,0) -> 0 | L12: =VLOOKUP(A12,[1]Sheet!$A:$J,10,0) -> 3 | M12: =L12/1.18 -> 2.5423729 | N12: =K12*C12 -> 0 | O12: =K12*H12 -> 0 | P12: =N12/8/60 -> 0 | Q12: =K12*D12 -> 0 | R12: =K12*E12 -> 0 | S12: =K12*E12*F12 -> 0 | T12: =K12*I12 -> 0 | U12: =K12*J12 -> 0 | V12: =K12*L12 -> 0 | W12: =V12/1.18 -> 0 | X12: =W12-U12 -> 0
A13: 8/G | B13: =VLOOKUP(A13,თვითღირებულება!A:AC,2,0) -> თასი მწვანე - S | C13: =VLOOKUP(A13,თვითღირებულება!A:AC,6,0) -> 1.3 | D13: =VLOOKUP(A13,თვითღირებულება!A:AC,15,0) -> 0.41 | E13: =VLOOKUP(A13,თვითღირებულება!A:AC,12,0) -> 0.42 | F13: =VLOOKUP(A13,თვითღირებულება!A:AC,11,0) -> 3.5 | G13: =E13*F13 -> 1.47 | H13: =VLOOKUP(A13,თვითღირებულება!A:AC,9,0) -> 0.49 | I13: =VLOOKUP(A13,თვითღირებულება!A:AC,16,0) -> 2.37 | J13: =VLOOKUP(A13,თვითღირებულება!A:AC,17,0) -> 2.0710169 | K13: =VLOOKUP(A13,[1]Sheet!$A:$G,7,0) -> 39 | L13: =VLOOKUP(A13,[1]Sheet!$A:$J,10,0) -> 3 | M13: =L13/1.18 -> 2.5423729 | N13: =K13*C13 -> 50.7 | O13: =K13*H13 -> 19.11 | P13: =N13/8/60 -> 0.105625 | Q13: =K13*D13 -> 15.99 | R13: =K13*E13 -> 16.38 | S13: =K13*E13*F13 -> 57.33 | T13: =K13*I13 -> 92.43 | U13: =K13*J13 -> 80.769661 | V13: =K13*L13 -> 117 | W13: =V13/1.18 -> 99.152542 | X13: =W13-U13 -> 18.382881
A14: 8/P | B14: =VLOOKUP(A14,თვითღირებულება!A:AC,2,0) -> თასი იასამნისფერი - S | C14: =VLOOKUP(A14,თვითღირებულება!A:AC,6,0) -> 1.3 | D14: =VLOOKUP(A14,თვითღირებულება!A:AC,15,0) -> 0.41 | E14: =VLOOKUP(A14,თვითღირებულება!A:AC,12,0) -> 0.42 | F14: =VLOOKUP(A14,თვითღირებულება!A:AC,11,0) -> 3.5 | G14: =E14*F14 -> 1.47 | H14: =VLOOKUP(A14,თვითღირებულება!A:AC,9,0) -> 0.49 | I14: =VLOOKUP(A14,თვითღირებულება!A:AC,16,0) -> 2.37 | J14: =VLOOKUP(A14,თვითღირებულება!A:AC,17,0) -> 2.0710169 | K14: =VLOOKUP(A14,[1]Sheet!$A:$G,7,0) -> 0 | L14: =VLOOKUP(A14,[1]Sheet!$A:$J,10,0) -> 3 | M14: =L14/1.18 -> 2.5423729 | N14: =K14*C14 -> 0 | O14: =K14*H14 -> 0 | P14: =N14/8/60 -> 0 | Q14: =K14*D14 -> 0 | R14: =K14*E14 -> 0 | S14: =K14*E14*F14 -> 0 | T14: =K14*I14 -> 0 | U14: =K14*J14 -> 0 | V14: =K14*L14 -> 0 | W14: =V14/1.18 -> 0 | X14: =W14-U14 -> 0
... A91: 49/R | B91: =VLOOKUP(A91,თვითღირებულება!A:AC,2,0) -> სითხეგაუმტარი ევრო ყუთი წითელი- L | C91: =VLOOKUP(A91,თვითღირებულება!A:AC,6,0) -> 3 | D91: =VLOOKUP(A91,თვითღირებულება!A:AC,15,0) -> 0.94 | E91: =VLOOKUP(A91,თვითღირებულება!A:AC,12,0) -> 3.8 | F91: =VLOOKUP(A91,თვითღირებულება!A:AC,11,0) -> 5 | G91: =E91*F91 -> 19 | H91: =VLOOKUP(A91,თვითღირებულება!A:AC,9,0) -> 2.88 | I91: =VLOOKUP(A91,თვითღირებულება!A:AC,16,0) -> 22.82 | J91: =VLOOKUP(A91,თვითღირებულება!A:AC,17,0) -> 19.482373 | K91: =VLOOKUP(A91,[1]Sheet!$A:$G,7,0) -> 0 | L91: =VLOOKUP(A91,[1]Sheet!$A:$J,10,0) -> 40 | M91: =L91/1.18 -> 33.898305 | N91: =K91*C91 -> 0 | O91: =K91*H91 -> 0 | P91: =N91/8/60 -> 0 | Q91: =K91*D91 -> 0 | R91: =K91*E91 -> 0 | S91: =K91*E91*F91 -> 0 | T91: =K91*I91 -> 0 | U91: =K91*J91 -> 0 | V91: =K91*L91 -> 0 | W91: =V91/1.18 -> 0 | X91: =W91-U91 -> 0
A92: 49/Y | B92: =VLOOKUP(A92,თვითღირებულება!A:AC,2,0) -> სითხეგაუმტარი ევრო ყუთი ყვითელი- L | C92: =VLOOKUP(A92,თვითღირებულება!A:AC,6,0) -> 3 | D92: =VLOOKUP(A92,თვითღირებულება!A:AC,15,0) -> 0.94 | E92: =VLOOKUP(A92,თვითღირებულება!A:AC,12,0) -> 3.8 | F92: =VLOOKUP(A92,თვითღირებულება!A:AC,11,0) -> 5 | G92: =E92*F92 -> 19 | H92: =VLOOKUP(A92,თვითღირებულება!A:AC,9,0) -> 2.88 | I92: =VLOOKUP(A92,თვითღირებულება!A:AC,16,0) -> 22.82 | J92: =VLOOKUP(A92,თვითღირებულება!A:AC,17,0) -> 19.482373 | K92: 1 | L92: 32 | M92: =L92/1.18 -> 27.118644 | N92: =K92*C92 -> 3 | O92: =K92*H92 -> 2.88 | P92: =N92/8/60 -> 0.00625 | Q92: =K92*D92 -> 0.94 | R92: =K92*E92 -> 3.8 | S92: =K92*E92*F92 -> 19 | T92: =K92*I92 -> 22.82 | U92: =K92*J92 -> 19.482373 | V92: =K92*L92 -> 32 | W92: =V92/1.18 -> 27.118644 | X92: =W92-U92 -> 7.6362712
A93: 50/BL | B93: =VLOOKUP(A93,თვითღირებულება!A:AC,2,0) -> სითხეგაუმტარი ევრო ყუთი შავი- S | C93: =VLOOKUP(A93,თვითღირებულება!A:AC,6,0) -> 3 | D93: =VLOOKUP(A93,თვითღირებულება!A:AC,15,0) -> 0.94 | E93: =VLOOKUP(A93,თვითღირებულება!A:AC,12,0) -> 2.52 | F93: =VLOOKUP(A93,თვითღირებულება!A:AC,11,0) -> 6.65 | G93: =E93*F93 -> 16.758 | H93: =VLOOKUP(A93,თვითღირებულება!A:AC,9,0) -> 2.88 | I93: =VLOOKUP(A93,თვითღირებულება!A:AC,16,0) -> 20.58 | J93: =VLOOKUP(A93,თვითღირებულება!A:AC,17,0) -> 17.584068 | K93: =VLOOKUP(A93,[1]Sheet!$A:$G,7,0) -> 0 | L93: =VLOOKUP(A93,[1]Sheet!$A:$J,10,0) -> 35 | M93: =L93/1.18 -> 29.661017 | N93: =K93*C93 -> 0 | O93: =K93*H93 -> 0 | P93: =N93/8/60 -> 0 | Q93: =K93*D93 -> 0 | R93: =K93*E93 -> 0 | S93: =K93*E93*F93 -> 0 | T93: =K93*I93 -> 0 | U93: =K93*J93 -> 0 | V93: =K93*L93 -> 0 | W93: =V93/1.18 -> 0 | X93: =W93-U93 -> 0
A94: 50/DB | B94: =VLOOKUP(A94,თვითღირებულება!A:AC,2,0) -> სითხეგაუმტარი ევრო ყუთი ლურჯი - S | C94: =VLOOKUP(A94,თვითღირებულება!A:AC,6,0) -> 3 | D94: =VLOOKUP(A94,თვითღირებულება!A:AC,15,0) -> 0.94 | E94: =VLOOKUP(A94,თვითღირებულება!A:AC,12,0) -> 2.52 | F94: =VLOOKUP(A94,თვითღირებულება!A:AC,11,0) -> 6.65 | G94: =E94*F94 -> 16.758 | H94: =VLOOKUP(A94,თვითღირებულება!A:AC,9,0) -> 2.88 | I94: =VLOOKUP(A94,თვითღირებულება!A:AC,16,0) -> 20.58 | J94: =VLOOKUP(A94,თვითღირებულება!A:AC,17,0) -> 17.584068 | K94: =VLOOKUP(A94,[1]Sheet!$A:$G,7,0) -> 0 | L94: =VLOOKUP(A94,[1]Sheet!$A:$J,10,0) -> 35 | M94: =L94/1.18 -> 29.661017 | N94: =K94*C94 -> 0 | O94: =K94*H94 -> 0 | P94: =N94/8/60 -> 0 | Q94: =K94*D94 -> 0 | R94: =K94*E94 -> 0 | S94: =K94*E94*F94 -> 0 | T94: =K94*I94 -> 0 | U94: =K94*J94 -> 0 | V94: =K94*L94 -> 0 | W94: =V94/1.18 -> 0 | X94: =W94-U94 -> 0
A95: 50/G | B95: =VLOOKUP(A95,თვითღირებულება!A:AC,2,0) -> სითხეგაუმტარი ევრო ყუთი მწვანე - S | C95: =VLOOKUP(A95,თვითღირებულება!A:AC,6,0) -> 3 | D95: =VLOOKUP(A95,თვითღირებულება!A:AC,15,0) -> 0.94 | E95: =VLOOKUP(A95,თვითღირებულება!A:AC,12,0) -> 2.52 | F95: =VLOOKUP(A95,თვითღირებულება!A:AC,11,0) -> 5 | G95: =E95*F95 -> 12.6 | H95: =VLOOKUP(A95,თვითღირებულება!A:AC,9,0) -> 2.88 | I95: =VLOOKUP(A95,თვითღირებულება!A:AC,16,0) -> 16.42 | J95: =VLOOKUP(A95,თვითღირებულება!A:AC,17,0) -> 14.058644 | K95: =VLOOKUP(A95,[1]Sheet!$A:$G,7,0) -> 0 | L95: =VLOOKUP(A95,[1]Sheet!$A:$J,10,0) -> 35 | M95: =L95/1.18 -> 29.661017 | N95: =K95*C95 -> 0 | O95: =K95*H95 -> 0 | P95: =N95/8/60 -> 0 | Q95: =K95*D95 -> 0 | R95: =K95*E95 -> 0 | S95: =K95*E95*F95 -> 0 | T95: =K95*I95 -> 0 | U95: =K95*J95 -> 0 | V95: =K95*L95 -> 0 | W95: =V95/1.18 -> 0 | X95: =W95-U95 -> 0
A96: 50/R | B96: =VLOOKUP(A96,თვითღირებულება!A:AC,2,0) -> სითხეგაუმტარი ევრო ყუთი წითელი - S | C96: =VLOOKUP(A96,თვითღირებულება!A:AC,6,0) -> 3 | D96: =VLOOKUP(A96,თვითღირებულება!A:AC,15,0) -> 0.94 | E96: =VLOOKUP(A96,თვითღირებულება!A:AC,12,0) -> 2.52 | F96: =VLOOKUP(A96,თვითღირებულება!A:AC,11,0) -> 5 | G96: =E96*F96 -> 12.6 | H96: =VLOOKUP(A96,თვითღირებულება!A:AC,9,0) -> 2.88 | I96: =VLOOKUP(A96,თვითღირებულება!A:AC,16,0) -> 16.42 | J96: =VLOOKUP(A96,თვითღირებულება!A:AC,17,0) -> 14.058644 | K96: =VLOOKUP(A96,[1]Sheet!$A:$G,7,0) -> 0 | L96: =VLOOKUP(A96,[1]Sheet!$A:$J,10,0) -> 35 | M96: =L96/1.18 -> 29.661017 | N96: =K96*C96 -> 0 | O96: =K96*H96 -> 0 | P96: =N96/8/60 -> 0 | Q96: =K96*D96 -> 0 | R96: =K96*E96 -> 0 | S96: =K96*E96*F96 -> 0 | T96: =K96*I96 -> 0 | U96: =K96*J96 -> 0 | V96: =K96*L96 -> 0 | W96: =V96/1.18 -> 0 | X96: =W96-U96 -> 0
A97: 59/BL | B97: =VLOOKUP(A97,თვითღირებულება!A:AC,2,0) -> ბოთლების ჩასადები ყუთი ბუდეებით შავი | C97: =VLOOKUP(A97,თვითღირებულება!A:AC,6,0) -> 1.7 | D97: =VLOOKUP(A97,თვითღირებულება!A:AC,15,0) -> 0.53 | E97: =VLOOKUP(A97,თვითღირებულება!A:AC,12,0) -> 1.72 | F97: =VLOOKUP(A97,თვითღირებულება!A:AC,11,0) -> 3.5 | G97: =E97*F97 -> 6.02 | H97: =VLOOKUP(A97,თვითღირებულება!A:AC,9,0) -> 1.63 | I97: =VLOOKUP(A97,თვითღირებულება!A:AC,16,0) -> 8.18 | J97: =VLOOKUP(A97,თვითღირებულება!A:AC,17,0) -> 7.0130508 | K97: =VLOOKUP(A97,[1]Sheet!$A:$G,7,0) -> 0 | L97: =VLOOKUP(A97,[1]Sheet!$A:$J,10,0) -> 15 | M97: =L97/1.18 -> 12.711864 | N97: =K97*C97 -> 0 | O97: =K97*H97 -> 0 | P97: =N97/8/60 -> 0 | Q97: =K97*D97 -> 0 | R97: =K97*E97 -> 0 | S97: =K97*E97*F97 -> 0 | T97: =K97*I97 -> 0 | U97: =K97*J97 -> 0 | V97: =K97*L97 -> 0 | W97: =V97/1.18 -> 0 | X97: =W97-U97 -> 0
A98: 60/BL | B98: =VLOOKUP(A98,თვითღირებულება!A:AC,2,0) -> ქილების სეპარატორი შავი | C98: =VLOOKUP(A98,თვითღირებულება!A:AC,6,0) -> 1.7 | D98: =VLOOKUP(A98,თვითღირებულება!A:AC,15,0) -> 0.53 | E98: =VLOOKUP(A98,თვითღირებულება!A:AC,12,0) -> 0.63 | F98: =VLOOKUP(A98,თვითღირებულება!A:AC,11,0) -> 3.5 | G98: =E98*F98 -> 2.205 | H98: =VLOOKUP(A98,თვითღირებულება!A:AC,9,0) -> 1.09 | I98: =VLOOKUP(A98,თვითღირებულება!A:AC,16,0) -> 3.83 | J98: =VLOOKUP(A98,თვითღირებულება!A:AC,17,0) -> 3.3266102 | K98: =VLOOKUP(A98,[1]Sheet!$A:$G,7,0) -> 1 | L98: =VLOOKUP(A98,[1]Sheet!$A:$J,10,0) -> 10 | M98: =L98/1.18 -> 8.4745763 | N98: =K98*C98 -> 1.7 | O98: =K98*H98 -> 1.09 | P98: =N98/8/60 -> 0.0035416667 | Q98: =K98*D98 -> 0.53 | R98: =K98*E98 -> 0.63 | S98: =K98*E98*F98 -> 2.205 | T98: =K98*I98 -> 3.83 | U98: =K98*J98 -> 3.3266102 | V98: =K98*L98 -> 10 | W98: =V98/1.18 -> 8.4745763 | X98: =W98-U98 -> 5.1479661
A99: 60/DB | B99: =VLOOKUP(A99,თვითღირებულება!A:AC,2,0) -> ქილების სეპარატორი ლურჯი | C99: =VLOOKUP(A99,თვითღირებულება!A:AC,6,0) -> 1.7 | D99: =VLOOKUP(A99,თვითღირებულება!A:AC,15,0) -> 0.53 | E99: =VLOOKUP(A99,თვითღირებულება!A:AC,12,0) -> 0.63 | F99: =VLOOKUP(A99,თვითღირებულება!A:AC,11,0) -> 3.5 | G99: =E99*F99 -> 2.205 | H99: =VLOOKUP(A99,თვითღირებულება!A:AC,9,0) -> 1.09 | I99: =VLOOKUP(A99,თვითღირებულება!A:AC,16,0) -> 3.83 | J99: =VLOOKUP(A99,თვითღირებულება!A:AC,17,0) -> 3.3266102 | K99: =VLOOKUP(A99,[1]Sheet!$A:$G,7,0) -> 0 | L99: =VLOOKUP(A99,[1]Sheet!$A:$J,10,0) -> 10 | M99: =L99/1.18 -> 8.4745763 | N99: =K99*C99 -> 0 | O99: =K99*H99 -> 0 | P99: =N99/8/60 -> 0 | Q99: =K99*D99 -> 0 | R99: =K99*E99 -> 0 | S99: =K99*E99*F99 -> 0 | T99: =K99*I99 -> 0 | U99: =K99*J99 -> 0 | V99: =K99*L99 -> 0 | W99: =V99/1.18 -> 0 | X99: =W99-U99 -> 0
A100: 74/BL | B100: =VLOOKUP(A100,თვითღირებულება!A:AC,2,0) -> ხილ-ბოსტნეულის ბადისებრი ყუთი შავი | C100: =VLOOKUP(A100,თვითღირებულება!A:AC,6,0) -> 0.75 | D100: =VLOOKUP(A100,თვითღირებულება!A:AC,15,0) -> 0.23 | E100: =VLOOKUP(A100,თვითღირებულება!A:AC,12,0) -> 0.5 | F100: =VLOOKUP(A100,თვითღირებულება!A:AC,11,0) -> 3.5 | G100: =E100*F100 -> 1.75 | H100: =VLOOKUP(A100,თვითღირებულება!A:AC,9,0) -> 0.72 | I100: =VLOOKUP(A100,თვითღირებულება!A:AC,16,0) -> 2.7 | J100: =VLOOKUP(A100,თვითღირებულება!A:AC,17,0) -> 2.3232203 | K100: =VLOOKUP(A100,[1]Sheet!$A:$G,7,0) -> 0 | L100: =VLOOKUP(A100,[1]Sheet!$A:$J,10,0) -> 2.5 | M100: =L100/1.18 -> 2.1186441 | N100: =K100*C100 -> 0 | O100: =K100*H100 -> 0 | P100: =N100/8/60 -> 0 | Q100: =K100*D100 -> 0 | R100: =K100*E100 -> 0 | S100: =K100*E100*F100 -> 0 | T100: =K100*I100 -> 0 | U100: =K100*J100 -> 0 | V100: =K100*L100 -> 0 | W100: =V100/1.18 -> 0 | X100: =W100-U100 -> 0
A101: 74/DB | B101: =VLOOKUP(A101,თვითღირებულება!A:AC,2,0) -> ხილ-ბოსტნეულის ბადისებრი ყუთი ლურჯი | C101: =VLOOKUP(A101,თვითღირებულება!A:AC,6,0) -> 0.75 | D101: =VLOOKUP(A101,თვითღირებულება!A:AC,15,0) -> 0.23 | E101: =VLOOKUP(A101,თვითღირებულება!A:AC,12,0) -> 0.5 | F101: =VLOOKUP(A101,თვითღირებულება!A:AC,11,0) -> 3.5 | G101: =E101*F101 -> 1.75 | H101: =VLOOKUP(A101,თვითღირებულება!A:AC,9,0) -> 0.72 | I101: =VLOOKUP(A101,თვითღირებულება!A:AC,16,0) -> 2.7 | J101: =VLOOKUP(A101,თვითღირებულება!A:AC,17,0) -> 2.3232203 | K101: =VLOOKUP(A101,[1]Sheet!$A:$G,7,0) -> 0 | L101: =VLOOKUP(A101,[1]Sheet!$A:$J,10,0) -> 2.5 | M101: =L101/1.18 -> 2.1186441 | N101: =K101*C101 -> 0 | O101: =K101*H101 -> 0 | P101: =N101/8/60 -> 0 | Q101: =K101*D101 -> 0 | R101: =K101*E101 -> 0 | S101: =K101*E101*F101 -> 0 | T101: =K101*I101 -> 0 | U101: =K101*J101 -> 0 | V101: =K101*L101 -> 0 | W101: =V101/1.18 -> 0 | X101: =W101-U101 -> 0 | Z101: =30000*Y102 -> 3453.8835
T102: =SUBTOTAL(9,T2:T101) -> 2205.25 | U102: =SUBTOTAL(9,U2:U101) -> 1914.7819 | V102: =SUM(V2:V101) -> 2614.65 | W102: =V102/1.18 -> 2215.8051 | X102: =SUBTOTAL(9,X2:X101) -> 301.02322 | Y102: =X102/V102 -> 0.11512945
X103: =V102*4% -> 104.586 | Y103: =X104/V102 -> 0.036883415
X104: =X102-V102*4%-100 -> 96.43722

Sheet დისტრიბუცია
A1: კოდი | B1: პროდუქტი | C1: ფასი | D1: ცალი | E1: ცალი | F1: ცალი | G1: ცალი | H1: ცალი | I1: ცალი | J1: ცალი | K1: ცალი | L1: ცალი | M1: რაოდენობა | N1: ღირებულება
A2: 1/DB | B2: ოვალური ვარცლი ლურჯი - L | C2: 6.5 | D2: 10 | E2: 2 | F2: 2 | M2: =SUM(D2:L2) -> 14 | N2: =M2*C2 -> 91 | P2: =SUM(N2:N107) -> 1313.55
A3: 2/DB | B3: ოვალური ვარცლი ლურჯი - M | C3: 5.95 | D3: 10 | E3: 5 | F3: 4 | G3: 10 | M3: =SUM(D3:L3) -> 29 | N3: =M3*C3 -> 172.55 | P3: 70 | Q3: საწვავი
A4: 3/DB | B4: ოვალური ვარცლი ლურჯი - S | C4: 5.45 | D4: 10 | E4: 5 | F4: 2 | M4: =SUM(D4:L4) -> 17 | N4: =M4*C4 -> 92.65 | P4: 10 | Q4: შოთა
A5: 4/DB | B5: მრგვალი ვარცლი ლურჯი - S | C5: 3.5 | D5: 10 | E5: 3 | F5: 2 | G5: 4 | H5: 3 | I5: 1 | M5: =SUM(D5:L5) -> 23 | N5: =M5*C5 -> 80.5 | P5: =P2-P3-P4 -> 1233.55
A6: 5/1/BL | B6: ინდუსტრიული ვარცლი შავი | C6: 12.75 | M6: =SUM(D6:L6) -> 0 | N6: =M6*C6 -> 0
A7: 5/DB | B7: უნივერსალური ვარცლი ლურჯი | C7: 8.5 | M7: =SUM(D7:L7) -> 0 | N7: =M7*C7 -> 0
A8: 6/DB | B8: გობი ერგონომიური სახელურებით ლურჯი - L | C8: 4.65 | M8: =SUM(D8:L8) -> 0 | N8: =M8*C8 -> 0
A9: 6/G | B9: გობი ერგონომიური სახელურებით მწვანე - L | C9: 4.65 | M9: =SUM(D9:L9) -> 0 | N9: =M9*C9 -> 0
A10: 6/R | B10: გობი ერგონომიური სახელურებით წითელი - L | C10: 4.65 | M10: =SUM(D10:L10) -> 0 | N10: =M10*C10 -> 0
A11: 7/DB | B11: გობი - M ლურჯი | C11: 3.85 | M11: =SUM(D11:L11) -> 0 | N11: =M11*C11 -> 0
A12: 8/DB | B12: თასი ლურჯი - S | C12: 3 | M12: =SUM(D12:L12) -> 0 | N12: =M12*C12 -> 0
A13: 8/G | B13: თასი მწვანე - S | C13: 3 | D13: 5 | E13: 2 | F13: 2 | G13: 6 | M13: =SUM(D13:L13) -> 15 | N13: =M13*C13 -> 45
A14: 8/P | B14: თასი იასამნისფერი - S | C14: 3 | M14: =SUM(D14:L14) -> 0 | N14: =M14*C14 -> 0
A15: 8/R | B15: თასი წითელი - S | C15: 3 | M15: =SUM(D15:L15) -> 0 | N15: =M15*C15 -> 0
A16: 9/DB | B16: პლასტმასის სათლი თავსახურით "ჰიდრო მაქსი" ლურჯი | C16: 6.8 | M16: =SUM(D16:L16) -> 0 | N16: =M16*C16 -> 0
A17: 10/BL | B17: პლასტმასის სათლი "სმარტ პლიუსი" შავი | C17: 3.75 | D17: 6 | E17: 10 | F17: 2 | M17: =SUM(D17:L17) -> 18 | N17: =M17*C17 -> 67.5
A18: 10-1/BL | B18: (დიდი) სანერგე ქოთანი დრენაჟით შავი | C18: 2.75 | D18: 5 | M18: =SUM(D18:L18) -> 5 | N18: =M18*C18 -> 13.75
A19: 11/DB | B19: გობი სახელურის გარეშე ლურჯი - XL | C19: 5.45 | D19: 5 | M19: =SUM(D19:L19) -> 5 | N19: =M19*C19 -> 27.25
A20: 12/DB | B20: პლასტმასის სათლი თავსახურით "ჰიდრო მინი" ლურჯი | C20: 6.4 | M20: =SUM(D20:L20) -> 0 | N20: =M20*C20 -> 0
A21: 13/1/BL | B21: ცილინდრული სათლი შავი | C21: 2.25 | D21: 1 | E21: 2 | F21: 4 | M21: =SUM(D21:L21) -> 7 | N21: =M21*C21 -> 15.75
A22: 13/BL | B22: პლასტმასის სათლი "სმარტი" შავი | C22: 3 | D22: 6 | E22: 10 | M22: =SUM(D22:L22) -> 16 | N22: =M22*C22 -> 48
A23: 14/DB | B23: მრგვალი ვარცლი ლურჯი - M | C23: 4.25 | M23: =SUM(D23:L23) -> 0 | N23: =M23*C23 -> 0
A24: 16/BL | B24: ინდუსტრიული სათლი შავი | C24: 7.65 | D24: 10 | E24: 5 | F24: 2 | M24: =SUM(D24:L24) -> 17 | N24: =M24*C24 -> 130.05
A25: 17/1/DB | B25: ოვალური აქანდაზი ლურჯი | C25: 1.7 | M25: =SUM(D25:L25) -> 0 | N25: =M25*C25 -> 0
A26: 17/1/G | B26: ოვალური აქანდაზი მწვანე | C26: 2 | M26: =SUM(D26:L26) -> 0 | N26: =M26*C26 -> 0
A27: 17/1R | B27: ოვალური აქანდაზი წითელი | C27: 2 | D27: 15 | E27: 10 | F27: 6 | G27: 10 | H27: 15 | M27: =SUM(D27:L27) -> 56 | N27: =M27*C27 -> 112
A28: 17/DB | B28: მართკუთხა აქანდაზი ლურჯი | C28: 1.55 | M28: =SUM(D28:L28) -> 0 | N28: =M28*C28 -> 0
A29: 18/DB | B29: ტარიანი ტოლჩა ლურჯი | C29: 1.55 | D29: 5 | M29: =SUM(D29:L29) -> 5 | N29: =M29*C29 -> 7.75
A30: 18/G | B30: ტარიანი ტოლჩა მწვანე | C30: 1.55 | M30: =SUM(D30:L30) -> 0 | N30: =M30*C30 -> 0
A31: 18/P | B31: ტარიანი ტოლჩა იასამნისფერი | C31: 1.55 | M31: =SUM(D31:L31) -> 0 | N31: =M31*C31 -> 0
A32: 19/BL | B32: გოდორი შავი | C32: 7.65 | D32: 10 | E32: 3 | F32: 10 | G32: 5 | H32: 2 | I32: 1 | M32: =SUM(D32:L32) -> 31 | N32: =M32*C32 -> 237.15
A33: 20/DB | B33: ღრმა პატარა ლანგარი ლურჯი | C33: 1.55 | M33: =SUM(D33:L33) -> 0 | N33: =M33*C33 -> 0
A34: 20/G | B34: ღრმა პატარა ლანგარი მწვანე | C34: 1.55 | M34: =SUM(D34:L34) -> 0 | N34: =M34*C34 -> 0
A35: 20/P | B35: ღრმა პატარა ლანგარი იასამნისფერი | C35: 1.55 | M35: =SUM(D35:L35) -> 0 | N35: =M35*C35 -> 0
A36: 20/R | B36: ღრმა პატარა ლანგარი წითელი | C36: 1.55 | M36: =SUM(D36:L36) -> 0 | N36: =M36*C36 -> 0
A37: 21/DB | B37: პლასტმასის სერვირების ლანგარი ლურჯი | C37: 2.75 | M37: =SUM(D37:L37) -> 0 | N37: =M37*C37 -> 0
A38: 21/G | B38: პლასტმასის სერვირების ლანგარი მწვანე | C38: 2.75 | M38: =SUM(D38:L38) -> 0 | N38: =M38*C38 -> 0
A39: 21/P | B39: პლასტმასის სერვირების ლანგარი იასამნისფერი | C39: 2.75 | M39: =SUM(D39:L39) -> 0 | N39: =M39*C39 -> 0
A40: 22/DB | B40: საწური ლურჯი | C40: 3 | M40: =SUM(D40:L40) -> 0 | N40: =M40*C40 -> 0
...

Sheet მაღაზია
A1: კოდი | B1: პროდუქტი | C1: ფასი | D1: ცალი | E1: რაოდენობა | F1: ჯამი | H1: =SUM(F5:F70) -> 872.25
A2: 1/DB | B2: ოვალური ვარცლი ლურჯი - L | C2: 6.5 | D2: 2 | E2: 0 | F2: =E2*C2 -> 0
A3: 2/DB | B3: ოვალური ვარცლი ლურჯი - M | C3: 5.95 | E3: =SUM(D3:D3) -> 0 | F3: =E3*C3 -> 0
A4: 3/DB | B4: ოვალური ვარცლი ლურჯი - S | C4: 5.45 | E4: =SUM(D4:D4) -> 0 | F4: =E4*C4 -> 0
A5: 4/DB | B5: მრგვალი ვარცლი ლურჯი - S | C5: =VLOOKUP(A5,თვითღირებულება!A:X,24,0) -> 3.9 | D5: 10 | E5: =SUM(D5:D5) -> 10 | F5: =E5*C5 -> 39
A6: 5/1/BL | B6: ინდუსტრიული ვარცლი შავი | C6: =VLOOKUP(A6,თვითღირებულება!A:X,24,0) -> 12.75 | D6: 5 | E6: =SUM(D6:D6) -> 5 | F6: =E6*C6 -> 63.75
A7: 5/DB | B7: უნივერსალური ვარცლი ლურჯი | C7: =VLOOKUP(A7,თვითღირებულება!A:X,24,0) -> 9 | E7: 10 | F7: =E7*C7 -> 90
A8: 6/DB | B8: გობი ერგონომიური სახელურებით ლურჯი - L | C8: 4.65 | E8: =SUM(D8:D8) -> 0 | F8: =E8*C8 -> 0
A9: 6/G | B9: გობი ერგონომიური სახელურებით მწვანე - L | C9: 4.65 | E9: =SUM(D9:D9) -> 0 | F9: =E9*C9 -> 0
A10: 6/R | B10: გობი ერგონომიური სახელურებით წითელი - L | C10: 4.65 | E10: =SUM(D10:D10) -> 0 | F10: =E10*C10 -> 0
A11: 7/DB | B11: გობი - M ლურჯი | C11: 3.85 | E11: =SUM(D11:D11) -> 0 | F11: =E11*C11 -> 0
A12: 8/DB | B12: თასი ლურჯი - S | C12: 3 | E12: =SUM(D12:D12) -> 0 | F12: =E12*C12 -> 0
A13: 8/G | B13: თასი მწვანე - S | C13: 3 | E13: =SUM(D13:D13) -> 0 | F13: =E13*C13 -> 0
A14: 8/P | B14: თასი იასამნისფერი - S | C14: 3 | E14: =SUM(D14:D14) -> 0 | F14: =E14*C14 -> 0
A15: 8/R | B15: თასი წითელი - S | C15: 3 | E15: =SUM(D15:D15) -> 0 | F15: =E15*C15 -> 0
A16: 9/DB | B16: პლასტმასის სათლი თავსახურით "ჰიდრო მაქსი" ლურჯი | C16: =VLOOKUP(A16,თვითღირებულება!A:X,24,0) -> 6.8 | D16: 5 | E16: =SUM(D16:D16) -> 5 | F16: =E16*C16 -> 34
A17: 10/BL | B17: პლასტმასის სათლი "სმარტ პლიუსი" შავი | C17: =VLOOKUP(A17,თვითღირებულება!A:X,24,0) -> 4 | D17: 15 | E17: =SUM(D17:D17) -> 15 | F17: =E17*C17 -> 60
A18: 10-1/BL | B18: (დიდი) სანერგე ქოთანი დრენაჟით შავი | C18: 2.75 | E18: =SUM(D18:D18) -> 0 | F18: =E18*C18 -> 0
A19: 11/DB | B19: გობი სახელურის გარეშე ლურჯი - XL | C19: 5.45 | E19: =SUM(D19:D19) -> 0 | F19: =E19*C19 -> 0
A20: 12/DB | B20: პლასტმასის სათლი თავსახურით "ჰიდრო მინი" ლურჯი | C20: =VLOOKUP(A20,თვითღირებულება!A:X,24,0) -> 6.4 | D20: 5 | E20: =SUM(D20:D20) -> 5 | F20: =E20*C20 -> 32
A21: 13/1/BL | B21: ცილინდრული სათლი შავი | C21: 2.25 | E21: =SUM(D21:D21) -> 0 | F21: =E21*C21 -> 0
A22: 13/BL | B22: პლასტმასის სათლი "სმარტი" შავი | C22: 3 | E22: =SUM(D22:D22) -> 0 | F22: =E22*C22 -> 0
A23: 14/DB | B23: მრგვალი ვარცლი ლურჯი - M | C23: =VLOOKUP(A23,თვითღირებულება!A:X,24,0) -> 5 | D23: 10 | E23: =SUM(D23:D23) -> 10 | F23: =E23*C23 -> 50
A24: 16/BL | B24: ინდუსტრიული სათლი შავი | C24: =VLOOKUP(A24,თვითღირებულება!A:X,24,0) -> 7.65 | D24: 16 | E24: 20 | F24: =E24*C24 -> 153
A25: 17/1/DB | B25: ოვალური აქანდაზი ლურჯი | C25: 1.7 | E25: =SUM(D25:D25) -> 0 | F25: =E25*C25 -> 0
A26: 17/1/G | B26: ოვალური აქანდაზი მწვანე | C26: 2 | E26: =SUM(D26:D26) -> 0 | F26: =E26*C26 -> 0
A27: 17/1R | B27: ოვალური აქანდაზი წითელი | C27: 2 | E27: =SUM(D27:D27) -> 0 | F27: =E27*C27 -> 0
A28: 17/DB | B28: მართკუთხა აქანდაზი ლურჯი | C28: 1.55 | E28: =SUM(D28:D28) -> 0 | F28: =E28*C28 -> 0
A29: 18/DB | B29: ტარიანი ტოლჩა ლურჯი | C29: 1.55 | E29: =SUM(D29:D29) -> 0 | F29: =E29*C29 -> 0
A30: 18/G | B30: ტარიანი ტოლჩა მწვანე | C30: 1.55 | E30: =SUM(D30:D30) -> 0 | F30: =E30*C30 -> 0
A31: 18/P | B31: ტარიანი ტოლჩა იასამნისფერი | C31: 1.55 | E31: =SUM(D31:D31) -> 0 | F31: =E31*C31 -> 0
A32: 19/BL | B32: გოდორი შავი | C32: 7.65 | E32: =SUM(D32:D32) -> 0 | F32: =E32*C32 -> 0
A33: 20/DB | B33: ღრმა პატარა ლანგარი ლურჯი | C33: 1.55 | E33: =SUM(D33:D33) -> 0 | F33: =E33*C33 -> 0
A34: 20/G | B34: ღრმა პატარა ლანგარი მწვანე | C34: 1.55 | E34: =SUM(D34:D34) -> 0 | F34: =E34*C34 -> 0
A35: 20/P | B35: ღრმა პატარა ლანგარი იასამნისფერი | C35: 1.55 | E35: =SUM(D35:D35) -> 0 | F35: =E35*C35 -> 0
A36: 20/R | B36: ღრმა პატარა ლანგარი წითელი | C36: 1.55 | E36: =SUM(D36:D36) -> 0 | F36: =E36*C36 -> 0
... A39: 21/P | B39: პლასტმასის სერვირების ლანგარი იასამნისფერი | C39: 2.75 | E39: =SUM(D39:D39) -> 0 | F39: =E39*C39 -> 0
A40: 22/DB | B40: საწური ლურჯი | C40: =VLOOKUP(A40,თვითღირებულება!A:X,24,0) -> 3 | D40: 5 | E40: =SUM(D40:D40) -> 5 | F40: =E40*C40 -> 15
A41: 22/G | B41: საწური მწვანე | C41: =VLOOKUP(A41,თვითღირებულება!A:X,24,0) -> 3 | D41: 5 | E41: =SUM(D41:D41) -> 5 | F41: =E41*C41 -> 15
A42: 22/P | B42: საწური იასამნისფერი | C42: 3 | E42: =SUM(D42:D42) -> 0 | F42: =E42*C42 -> 0
...

Sheet კალკულატორი ახალი
A1: კოდი | B1: პროდუქტი | C1: დამზადების დრო წთ | D1: ერთეულზე დახარჯული ხელფასი | E1: რეალური წონა | F1: მასალის ფასი | G1: გამოყენებული მასალის ღირებულება | H1: ერთეულზე დახარჯული ელ. ენერგია | I1: ერთეულის თვითღირებულება | J1: ცალი | K1: გასაყიდი ფასი | L1: დამზადების დრო სთ | M1: დახარჯული ელ. ენერგია ლარი | N1: დამზადების დრო დღე | O1: სამუსაო საათების ღირებულება | P1: გამოსაყენებელი მასალა კგ | Q1: გამოსაყენებელი მასალის ღირებულება | R1: თვითღირებულება სულ | S1: ჩასათვლელი დღგ | T1: თვითღირებულებადღგ გარეშე | U1: შემოსავალი | V1: დღგ | W1: გასაყიდი დღგ გარეშე | X1: გადასახდელი დღგ | Y1: მოგება
A2: 23/DB | B2: =VLOOKUP(A2,თვითღირებულება!A:B,2,0) -> პლასტმასის ანატომიური სავარძელი ლურჯი | C2: =VLOOKUP(A2,თვითღირებულება!A:F,6,0) -> 1.8 | D2: =VLOOKUP(A2,თვითღირებულება!A:O,15,0) -> 0.56 | E2: =VLOOKUP(A2,თვითღირებულება!A:L,12,0) -> 1.27 | F2: 7 | G2: =F2*E2 -> 8.89 | H2: =VLOOKUP(A2,თვითღირებულება!A:I,9,0) -> 1.15 | I2: =ROUND(H2+G2+D2,2) -> 10.6 | J2: 9000 | K2: 22 | L2: =J2*C2/60 -> 270 | M2: =J2*H2 -> 10350 | N2: =L2/8 -> 33.75 | O2: =J2*D2 -> 5040 | P2: =J2*E2 -> 11430 | Q2: =P2*F2 -> 80010 | R2: =Q2+O2+M2 -> 95400 | S2: =(Q2-Q2/1.18)+(M2-M2/1.18) -> 13783.729 | T2: =R2-S2 -> 81616.271 | U2: =J2*K2 -> 198000 | V2: =U2-U2/1.18 -> 30203.39 | W2: =U2-V2 -> 167796.61 | X2: =V2-S2 -> 16419.661 | Y2: =U2-V2-R2+S2 -> 86180.339
